// ISSUE: Unittests with succeeding asserts should not halt the program
// NO_OUTPUT: true
// COMPILE_OPTIONS: unittest

unittest {
    assert(1 == 1, "1 equals 1");
}

func main() {}
